<?xml version="1.0" encoding="UTF-8"?>
<!-- Generated by org.testng.reporters.JUnitReportReporter -->
<testsuite hostname="DESKTOP-15S6U3P" failures="1" tests="3" name="testLayer.TransferFundsTest" time="19.848" errors="0" timestamp="2023-01-11T05:06:44 EST" skipped="1">
  <testcase classname="testLayer.TransferFundsTest" name="TransferFunds_Valid" time="12.519"/>
  <system-out/>
  <testcase classname="testLayer.TransferFundsTest" name="TransferFunds_InvalidToAcc" time="7.329">
    <failure message="expected [false] but found [true]" type="java.lang.AssertionError">
      <![CDATA[java.lang.AssertionError: expected [false] but found [true]
at org.testng.Assert.fail(Assert.java:99)
at org.testng.Assert.failNotEquals(Assert.java:1037)
at org.testng.Assert.assertEqualsImpl(Assert.java:140)
at org.testng.Assert.assertEquals(Assert.java:122)
at org.testng.Assert.assertEquals(Assert.java:819)
at org.testng.Assert.assertEquals(Assert.java:829)
at testLayer.TransferFundsTest.TransferFunds_InvalidToAcc(TransferFundsTest.java:75)
at java.base/jdk.internal.reflect.NativeMethodAccessorImpl.invoke0(Native Method)
at java.base/jdk.internal.reflect.NativeMethodAccessorImpl.invoke(NativeMethodAccessorImpl.java:77)
at java.base/jdk.internal.reflect.DelegatingMethodAccessorImpl.invoke(DelegatingMethodAccessorImpl.java:43)
at java.base/java.lang.reflect.Method.invoke(Method.java:568)
at org.testng.internal.MethodInvocationHelper.invokeMethod(MethodInvocationHelper.java:133)
at org.testng.internal.TestInvoker.invokeMethod(TestInvoker.java:598)
at org.testng.internal.TestInvoker.invokeTestMethod(TestInvoker.java:173)
at org.testng.internal.MethodRunner.runInSequence(MethodRunner.java:46)
at org.testng.internal.TestInvoker$MethodInvocationAgent.invoke(TestInvoker.java:824)
at org.testng.internal.TestInvoker.invokeTestMethods(TestInvoker.java:146)
at org.testng.internal.TestMethodWorker.invokeTestMethods(TestMethodWorker.java:146)
at org.testng.internal.TestMethodWorker.run(TestMethodWorker.java:128)
at java.base/java.util.ArrayList.forEach(ArrayList.java:1511)
at org.testng.TestRunner.privateRun(TestRunner.java:794)
at org.testng.TestRunner.run(TestRunner.java:596)
at org.testng.SuiteRunner.runTest(SuiteRunner.java:377)
at org.testng.SuiteRunner.access$000(SuiteRunner.java:28)
at org.testng.SuiteRunner$SuiteWorker.run(SuiteRunner.java:418)
at org.testng.internal.thread.ThreadUtil.lambda$execute$0(ThreadUtil.java:64)
at java.base/java.util.concurrent.FutureTask.run(FutureTask.java:264)
at java.base/java.util.concurrent.ThreadPoolExecutor.runWorker(ThreadPoolExecutor.java:1136)
at java.base/java.util.concurrent.ThreadPoolExecutor$Worker.run(ThreadPoolExecutor.java:635)
at java.base/java.lang.Thread.run(Thread.java:833)
]]>
    </failure>
  </testcase> <!-- TransferFunds_InvalidToAcc -->
  <system-out/>
  <testcase classname="testLayer.TransferFundsTest" name="TransferFunds_InvalidAmount" time="0.000">
    <skipped/>
  </testcase> <!-- TransferFunds_InvalidAmount -->
  <system-out/>
</testsuite> <!-- testLayer.TransferFundsTest -->
